<mujoco model="conveyer">


  <default>
    <joint damping=".3" axis="0 1 0"/>
    <geom type="box" friction=".5"/>
    <default class="wall">
      <geom rgba=".5 .5 .5 .4"/>
    </default>
       
  </default>
  <worldbody>
    <body name="conveyer" pos="0.25 0 0.5">
      <joint name="conveyor" type="slide" damping="100" axis="0 1 0"/>
      <geom size=".1 .2 .01" pos="0 0 -.01"/>
      <!-- <geom size=".01 .08 .031" pos="-.19 0 .03" class="wall"/> -->
      <!-- <geom size=".01 .08 .031" pos="0  0 .03" class="wall"/> -->
      <!-- <geom size=".01 .08 .031" pos="0.19 0 .03" class="wall"/> -->
      <!-- <geom size="0.2 .01 .031" pos="0 -.09 .03" class="wall"/> -->
      <!-- <geom size="0.2 .01 .031" pos="0 0.09 .03" class="wall"/> -->
    </body>
     
        
  </worldbody>

  <actuator>
    <position name="conveyor" 
              joint="conveyor" 
              ctrlrange="0 0.5" 
              ctrllimited="true" 
              kp="400"
              />
    <!-- <position name="conveyor" 
              joint="conveyor" 
              kp="400"
              /> -->

  </actuator>


</mujoco>