<mujoco model="kinova3">
    <actuator>
        <!-- Physical limits of the actuator. Pulled directly from datasheet. See pg 24 of:
         https://www.kinovarobotics.com/sites/default/files/UG-014_KINOVA_Gen3_Ultra_lightweight_robot_User_guide_EN_R06_0.pdf -->
        <motor ctrllimited="true" ctrlrange="-32.0 32.0" joint="Actuator1" name="torq_j1"/>
        <motor ctrllimited="true" ctrlrange="-32.0 32.0" joint="Actuator2" name="torq_j2"/>
        <motor ctrllimited="true" ctrlrange="-32.0 32.0" joint="Actuator3" name="torq_j3"/>
        <motor ctrllimited="true" ctrlrange="-32.0 32.0" joint="Actuator4" name="torq_j4"/>
        <motor ctrllimited="true" ctrlrange="-32.0 32.0" joint="Actuator5" name="torq_j5"/>
        <motor ctrllimited="true" ctrlrange="-13.0 13.0" joint="Actuator6" name="torq_j6"/>
        <motor ctrllimited="true" ctrlrange="-13.0 13.0" joint="Actuator7" name="torq_j7"/>

        <position ctrllimited="true" ctrlrange="-0.0115 0.020833" joint="r_finger_joint" kp="1000" name="gripper_r_finger_joint" forcelimited="true" forcerange="-20 20"/>
        <position ctrllimited="true" ctrlrange="-0.020833 0.0115" joint="l_finger_joint" kp="1000" name="gripper_l_finger_joint" forcelimited="true" forcerange="-20 20"/>    
    
    </actuator>
    <asset>

        <mesh name="base_link" file="meshes/base_link.stl" />
        <mesh name="shoulder_link" file="meshes/shoulder_link.stl" />
        <mesh name="half_arm_1_link" file="meshes/half_arm_1_link.stl" />
        <mesh name="half_arm_2_link" file="meshes/half_arm_2_link.stl" />
        <mesh name="forearm_link" file="meshes/forearm_link.stl" />
        <mesh name="spherical_wrist_1_link" file="meshes/spherical_wrist_1_link.stl" />
        <mesh name="spherical_wrist_2_link" file="meshes/spherical_wrist_2_link.stl" />
        <mesh name="bracelet_with_vision_link" file="meshes/bracelet_with_vision_link.stl" />


        <mesh name="electric_gripper_base" file="meshes/rethink_gripper/electric_gripper_base.stl" />
        <mesh name="standard_narrow" file="meshes/rethink_gripper/standard_narrow.stl" />
        <mesh name="half_round_tip" file="meshes/rethink_gripper/half_round_tip.stl" />
        <mesh name="connector_plate" file="meshes/rethink_gripper/connector_plate.stl" />    
    
    
    </asset>
    <worldbody>

    
        <body name="base" pos="0 0 0">
            <!-- robot view -->
            <camera mode="fixed" name="robotview" pos="1.0 0 0.4" quat="0.653 0.271 0.271 0.653"/>
            <inertial diaginertia="0 0 0" mass="0" pos="0 0 0"/>
            <!-- mount attached here -->
            <geom type="mesh" contype="0" conaffinity="0" group="1" rgba="1 1 1 1" mesh="base_link" />
            <geom type="mesh" conaffinity="0" rgba="0.75294 0.75294 0.75294 1" mesh="base_link" name="base_collision" />
            <body name="shoulder_link" pos="0 0 0.15643" quat="-3.67321e-06 1 0 0">
                <inertial pos="-2.3e-05 -0.010364 -0.07336" quat="0.707051 0.0451246 -0.0453544 0.704263" mass="1.3773" diaginertia="0.00488868 0.00457 0.00135132" />
                <joint name="Actuator1" pos="0 0 0" axis="0 0 1" damping="0.1" />
                <geom type="mesh" contype="0" conaffinity="0" group="1" rgba="1 1 1 1" name="s_visual" mesh="shoulder_link" />
                <geom type="mesh" conaffinity="0" rgba="0.75294 0.75294 0.75294 1" mesh="shoulder_link" name="s_collision"/>
                <body name="HalfArm1_Link" pos="0 0.005375 -0.12838" quat="0.707105 0.707108 0 0">
                    <inertial pos="-4.4e-05 -0.09958 -0.013278" quat="0.482348 0.516286 -0.516862 0.483366" mass="1.1636" diaginertia="0.0113017 0.011088 0.00102532" />
                    <joint name="Actuator2" pos="0 0 0" axis="0 0 1" limited="true" range="-2.41 2.41" damping="0.1" />
                    <geom type="mesh" contype="0" conaffinity="0" group="1" rgba="1 1 1 1" name="ha1_visual" mesh="half_arm_1_link" />
                    <geom type="mesh" conaffinity="0" rgba="0.75294 0.75294 0.75294 1" mesh="half_arm_1_link" name="ha1_collision"/>
                    <body name="HalfArm2_Link" pos="0 -0.21038 -0.006375" quat="0.707105 -0.707108 0 0">
                        <inertial pos="-4.4e-05 -0.006641 -0.117892" quat="0.706144 0.0213722 -0.0209128 0.707437" mass="1.1636" diaginertia="0.0111633 0.010932 0.00100671" />
                        <joint name="Actuator3" pos="0 0 0" axis="0 0 1" damping="0.1" />
                        <geom type="mesh" contype="0" conaffinity="0" group="1" rgba="1 1 1 1" name="ha2_visual" mesh="half_arm_2_link" />
                        <geom type="mesh" conaffinity="0" rgba="0.75294 0.75294 0.75294 1" mesh="half_arm_2_link" name="ha2_collision"/>
                        <body name="forearm_link" pos="0 0.006375 -0.21038" quat="0.707105 0.707108 0 0">
                            <inertial pos="-1.8e-05 -0.075478 -0.015006" quat="0.483678 0.515961 -0.515859 0.483455" mass="0.9302" diaginertia="0.00834839 0.008147 0.000598606" />
                            <joint name="Actuator4" pos="0 0 0" axis="0 0 1" limited="true" range="-2.66 2.66" damping="0.1" />
                            <geom type="mesh" contype="0" conaffinity="0" group="1" rgba="1 1 1 1" name="f_visual" mesh="forearm_link" />
                            <geom type="mesh" conaffinity="0" rgba="0.75294 0.75294 0.75294 1" mesh="forearm_link" name="f_collision"/>
                            <body name="SphericalWrist1_Link" pos="0 -0.20843 -0.006375" quat="0.707105 -0.707108 0 0">
                                <inertial pos="1e-06 -0.009432 -0.063883" quat="0.703558 0.0707492 -0.0707492 0.703558" mass="0.6781" diaginertia="0.00165901 0.001596 0.000346988" />
                                <joint name="Actuator5" pos="0 0 0" axis="0 0 1" damping="0.1" />
                                <geom type="mesh" contype="0" conaffinity="0" group="1" rgba="1 1 1 1" name="w1_visual" mesh="spherical_wrist_1_link" />
                                <geom type="mesh" conaffinity="0" rgba="0.75294 0.75294 0.75294 1" mesh="spherical_wrist_1_link" name="w1_collision"/>
                                <body name="SphericalWrist2_Link" pos="0 0.00017505 -0.10593" quat="0.707105 0.707108 0 0">
                                    <inertial pos="1e-06 -0.045483 -0.00965" quat="0.44426 0.550121 -0.550121 0.44426" mass="0.6781" diaginertia="0.00170087 0.001641 0.00035013" />
                                    <joint name="Actuator6" pos="0 0 0" axis="0 0 1" limited="true" range="-2.23 2.23" damping="0.01" />
                                    <geom type="mesh" contype="0" conaffinity="0" group="1" rgba="1 1 1 1" name="w2_visual" mesh="spherical_wrist_2_link" />
                                    <geom type="mesh" conaffinity="0" rgba="0.75294 0.75294 0.75294 1" mesh="spherical_wrist_2_link" name="w2_collision"/>
                                    <body name="Bracelet_Link" pos="0 -0.10593 -0.00017505" quat="0.707105 -0.707108 0 0">
                                        <inertial pos="-0.000281 -0.011402 -0.029798" quat="0.601961 0.40663 -0.381169 0.571843" mass="0.5006" diaginertia="0.000657515 0.000586793 0.000320693" />
                                        <joint name="Actuator7" pos="0 0 0" axis="0 0 1" damping="0.01" />
                                        <geom type="mesh" contype="0" conaffinity="0" group="1" rgba="1 1 1 1" name="b_visual" mesh="bracelet_with_vision_link" />
                                        <geom type="mesh" conaffinity="0" rgba="0.75294 0.75294 0.75294 1" mesh="bracelet_with_vision_link" name="b_collision"/>
                                        <body name="right_hand" pos="0 0 -0.065" quat="0 0.707105 -0.707108 0">
                                            <!-- This camera points out from the eef. -->
                                            <camera mode="fixed" name="eye_in_hand" pos="0.05 0 0" quat="0 0.707108 0.707108 0" fovy="75"/>
                                            <!-- To add gripper -->
                                        
                                                <body name="gripper_base" pos="0 0 0">
                                                    <site name="ft_frame" pos="0 0 0" size="0.01 0.01 0.01" rgba="1 0 0 1" type="sphere" group="1"/>
                                                    <inertial pos="0 0 0" quat="-0.5 0.5 0.5 0.5" mass="0.3" diaginertia="3e-08 2e-08 2e-08" />
                                                    <geom type="mesh" contype="0" conaffinity="0" group="1" mesh="connector_plate" name="connector_plate" pos="0 0 0.0018" rgba="0.499 0.499 0.499 1"/>
                                                    <geom type="mesh" contype="0" conaffinity="0" group="1" mesh="electric_gripper_base" name="electric_gripper_base" pos="0 0 0.0194" rgba="0.499 0.499 0.499 1"/>
                                                    <geom size="0.029 0.05" quat="0 0 0.707107 0.707107" type="cylinder" group="0" name="gripper_base_col" pos="0.004 0.0 0.04"/>
                                                    <!-- This site was added for visualization. -->
                                                    <body name="eef" pos="0 0 0.109" quat="0.707105 0 0 -0.707105">
                                                        <site name="grip_site" pos="0 0 0" size="0.01 0.01 0.01" rgba="1 0 0 0.5" type="sphere" group="1"/>
                                                        <site name="ee_x" pos="0.1 0 0" size="0.005 .1"  quat="0.707105  0 0.707108 0 " rgba="1 0 0 0" type="cylinder" group="1"/>
                                                        <site name="ee_y" pos="0 0.1 0" size="0.005 .1" quat="0.707105 0.707108 0 0" rgba="0 1 0 0" type="cylinder" group="1"/>
                                                        <site name="ee_z" pos="0 0 0.1" size="0.005 .1" quat="1 0 0 0" rgba="0 0 1 0" type="cylinder" group="1"/>
                                                        <!-- This site was added for visualization. -->
                                                        <site name="grip_site_cylinder" pos="0 0 0" size="0.005 10" rgba="0 1 0 0.3" type="cylinder" group="1"/>
                                                    </body>
                                                    <body name="l_finger" pos="0 0.01 0.0444">
                                                        <inertial pos="0 0 0" quat="0 0 0 -1" mass="0.02" diaginertia="0.01 0.01 0.01" />
                                                        <joint name="l_finger_joint" pos="0 0 0" axis="0 1 0" type="slide" limited="true" range="-0.0115 0.020833" damping="100" armature="1.0" frictionloss="1.0"/>
                                                        <geom name="l_finger" quat="0 0 0 -1" type="mesh" contype="0" conaffinity="0" group="1" mesh="standard_narrow" rgba="0.499 0.499 0.499 1"/>
                                                        <geom size="0.005 0.00675 0.0375" pos="0 0.01725 0.04" quat="0 0 0 -1" type="box" group="0" conaffinity="1" contype="0" name="l_finger_g0" friction="0 0 0"/>
                                                        <geom size="0.005 0.025 0.0085" pos="-0.005 -0.003 0.0083" quat="0 0 0 -1" type="box" group="0" conaffinity="1" contype="0" name="l_finger_g1" friction="0 0 0"/>
                                                        <body name="l_finger_tip" pos="0 0.01725 0.075">
                                                            <inertial pos="0 0 0" quat="0 0 0 1" mass="0.01" diaginertia="0.01 0.01 0.01" />
                                                            <geom name="l_fingertip_g0_vis" quat="0 0 0 1" type="mesh" contype="0" conaffinity="0" group="1" mesh="half_round_tip" rgba="0.499 0.499 0.499 1"/>
                                                            <geom size="0.004 0.004 0.0185" pos="0 -0.0045 -0.015" quat="0 0 0 -1" type="box" group="0"  conaffinity="1" contype="0" name="l_fingertip_g0" friction="0 0 0"/>
                                                            <geom size="0.0035 0.004 0.0165" pos="0 -0.0047 -0.017" type="box"  conaffinity="1" contype="0" name="l_fingerpad_g0" friction="0 0 0"/>
                                                        </body>
                                                    </body>
                                                    <body name="r_finger" pos="0 -0.01 0.0444">
                                                        <inertial pos="0 0 0" mass="0.02" diaginertia="0.01 0.01 0.01" />
                                                        <joint name="r_finger_joint" pos="0 0 0" axis="0 1 0" type="slide" limited="true" range="-0.020833 0.0115" damping="100" armature="1.0" frictionloss="1.0"/>
                                                        <geom name="r_finger" type="mesh" contype="0" conaffinity="0" group="1" mesh="standard_narrow" rgba="0.499 0.499 0.499 1"/>
                                                        <geom size="0.005 0.00675 0.0375" pos="0 -0.01725 0.04" type="box" group="0" conaffinity="1" contype="0" name="r_finger_g0" friction="0 0 0"/>
                                                        <geom size="0.005 0.025 0.0085" pos="0.005 0.003 0.0083" type="box" group="0" conaffinity="1" contype="0" name="r_finger_g1" friction="0 0 0"/>
                                                        <body name="r_finger_tip" pos="0 -0.01725 0.075">
                                                            <inertial pos="0 0 0" mass="0.01" diaginertia="0.01 0.01 0.01" />
                                                            <geom name="r_fingertip_g0_vis" type="mesh" contype="0" conaffinity="0" group="1" mesh="half_round_tip" rgba="0.499 0.499 0.499 1"/>
                                                            <geom size="0.004 0.004 0.0185" pos="0 0.0045 -0.015" type="box" group="0" conaffinity="1" contype="0" name="r_fingertip_g0" friction="0 0 0"/>
                                                            <geom size="0.0035 0.004 0.0165" pos="0 0.0047 -0.017" type="box"  conaffinity="1" contype="0" name="r_fingerpad_g0" friction="0 0 0"/>
                                                        </body>
                                                    </body>
                                                </body>
                                        
                                        
                                        </body>
                                    </body>
                                </body>
                            </body>
                        </body>
                    </body>
                </body>
            </body>
        </body>
    </worldbody>

    <sensor>
        <force name="force_ee" site="ft_frame"/>
        <torque name="torque_ee" site="ft_frame"/>
    </sensor>




</mujoco>
